Workbook

Sheet MATERIAL BALANCE
A2: NATURAL GAS | C2: =C4/0.97 -> 1430.7732 | E2: DESULPHARISER | J2: PRIMARY REFORMER | M2: =0.7 -> 0.7 | O2: AIR | P2: =P4/0.78 -> 2138.5641 | S2: SECONDARY REFORMER | U2: 0.95 | X2: WATER GAS SHIFT REACTION | AA2: =0.95 -> 0.95 | AC2: CO2 REMOVAL | AG2: OXIDATION | AM2: PREESURE SWING ADSORPTION | AQ2: HB COMPRESSOR | AV2: REACTOR | BA2: RECYCLE | BB2: =4.5 -> 4.5 | BD2: PURGE | BG2: PRODUCT
E3: INPUT | G3: OUTPUT | J3: INPUT | L3: OUTPUT | R3: INPUT | T3: OUTPUT | W3: INPUT | Y3: OUTPUT | AB3: INLET | AD3: OUTLET | AG3: INLET | AI3: OUTLET | AL3: INLET | AN3: OUTLET | AQ3: INLET | AS3: OUTLET | AV3: INLET | AX3: OUTLET
B4: CH4 | C4: =1387.85 -> 1387.85 | E4: CH4 | F4: =C4 -> 1387.85 | G4: H2O | H4: =F5 -> 42.923196 | J4: H2O | K4: =3*H6 -> 4163.55 | L4: CH4 | M4: =416.35 -> 416.35 | O4: N2 | P4: =AR4 -> 1668.08 | R4: N2 | S4: =P4 -> 1668.08 | T4: N2 | U4: =S4 -> 1668.08 | W4: N2 | X4: =U4 -> 1668.08 | Y4: N2 | Z4: =X4 -> 1668.08 | AB4: N2 | AC4: =Z4 -> 1668.08 | AD4: N2 | AE4: =AC4 -> 1668.08 | AG4: N2 | AH4: =AE4 -> 1668.08 | AI4: N2 | AJ4: =AH4 -> 1668.08 | AL4: N2 | AM4: =AR4 -> 1668.08 | AN4: N2 | AO4: =AR4 -> 1668.08 | AQ4: N2 | AR4: =1668.08 -> 1668.08 | AS4: N2 | AT4: =AW4 -> 9191.1765 | AV4: N2 | AW4: =AY7/(2*0.16) -> 9191.1765 | AX4: N2 | AY4: =0.84*AW4 -> 7720.5882 | BA4: N2 | BB4: =BB2*AR4 -> 7506.36 | BD4: N2 | BE4: =AY4-BB4 -> 214.22824 | BG4: NH3
B5: H2S | C5: =C2*0.03 -> 42.923196 | E5: H2S | F5: =C5 -> 42.923196 | G5: ZnS | H5: =F6 -> 42.923196 | J5: CH4 | K5: =H6 -> 1387.85 | L5: CO | M5: =L13 -> 971.5 | O5: O2 | P5: =P2*0.21 -> 449.09846 | R5: O2 | S5: =P5 -> 449.09846 | T5: O2 | U5: =S5-(0.5*T14) -> 251.33221 | W5: O2 | X5: =U5 -> 251.33221 | Y5: O2 | Z5: =X5 -> 251.33221 | AB5: O2 | AC5: =Z5 -> 251.33221 | AD5: O2 | AE5: =AC5 -> 251.33221 | AG5: O2 | AH5: =AE5 -> 251.33221 | AI5: O2 | AJ5: =AH5-AI14 -> 217.1564 | AL5: O2 | AM5: =AJ5 -> 217.1564 | AN5: O2 | AO5: =AM5 -> 217.1564 | AQ5: H2 | AR5: =AO8 -> 5004.2459 | AS5: H2 | AT5: =AW5 -> 27573.529 | AV5: H2 | AW5: =3*AW4 -> 27573.529 | AX5: H2 | AY5: =AW5-3*AX11 -> 23161.765 | BA5: H2 | BB5: =4.5*AR5 -> 22519.106 | BD5: H2 | BE5: =AY5-BB5 -> 642.65827 | BG5: =((50*1000)/17) -> 2941.1765
E6: ZnO | F6: =C5 -> 42.923196 | G6: CH4 | H6: =F4 -> 1387.85 | L6: H2 | M6: =3*L13 -> 2914.5 | O6: INERT | P6: =AR6 -> 19.58 | R6: INERT | S6: =P6 -> 19.58 | T6: INERT | U6: =S6 -> 19.58 | W6: INERT | X6: =U6 -> 19.58 | Y6: INERT | Z6: =X6 -> 19.58 | AB6: INERT | AC6: =Z6 -> 19.58 | AD6: INERT | AE6: =AC6 -> 19.58 | AG6: INERT | AH6: =AE6 -> 19.58 | AI6: INERT | AJ6: =AH6 -> 19.58 | AL6: INERT | AM6: =AJ6 -> 19.58 | AN6: INERT | AO6: =AM6 -> 19.58 | AQ6: INERT | AR6: =19.58 -> 19.58 | AS6: INERT | AT6: =AR6+BB6 -> 107.69 | AV6: INERT | AW6: =AT6 -> 107.69 | AX6: INERT | AY6: =AW6 -> 107.69 | BA6: INERT | BB6: =4.5*AR6 -> 88.11 | BD6: INERT | BE6: =AY6-BB6 -> 19.58
L7: H2O | M7: =K4-L13 -> 3192.05 | R7: CH4 | S7: =M4 -> 416.35 | T7: CH4 | U7: =(1-U2)*S7 -> 20.8175 | W7: CH4 | X7: =U7 -> 20.8175 | Y7: CH4 | Z7: =X7 -> 20.8175 | AB7: CH4 | AC7: =Z7 -> 20.8175 | AD7: CH4 | AE7: =AC7 -> 20.8175 | AG7: CH4 | AH7: =AE7 -> 20.8175 | AI7: CH4 | AJ7: =AH7 -> 20.8175 | AL7: CH4 | AM7: =AJ7 -> 20.8175 | AN7: CH4 | AO7: =AM7 -> 20.8175 | AX7: NH3 | AY7: =BG5 -> 2941.1765
R8: CO | S8: =M5 -> 971.5 | T8: H2 | U8: =S9+2*T14 -> 3705.565 | W8: H2 | X8: =U8 -> 3705.565 | Y8: H2 | Z8: =X8+Y14 -> 5004.2459 | AB8: H2 | AC8: =Z8 -> 5004.2459 | AD8: H2 | AE8: =AC8 -> 5004.2459 | AG8: H2 | AH8: =AE8 -> 5004.2459 | AI8: H2 | AJ8: =AH8 -> 5004.2459 | AL8: H2 | AM8: =AJ8 -> 5004.2459 | AN8: H2 | AO8: =AM8 -> 5004.2459 | BE8: =SUM(BE4:BE6) -> 876.4665
R9: H2 | S9: =M6 -> 2914.5 | T9: CO | U9: =S8+T14 -> 1367.0325 | W9: CO | X9: =U9 -> 1367.0325 | Y9: CO | Z9: =X9*(1-AA2) -> 68.351625 | AB9: CO | AC9: =Z9 -> 68.351625 | AD9: CO | AE9: =AC9 -> 68.351625 | AG9: CO | AH9: =AE9 -> 68.351625 | AI9: CO2 | AJ9: =2*AI14 -> 68.351625 | AL9: CO2 | AM9: =AJ9 -> 68.351625 | AN9: H2O | AO9: =AM10 -> 594.68825 | BB9: =SUM(BB4:BB5) -> 30025.466
R10: H2O | S10: =M7 -> 3192.05 | T10: H2O | U10: =S10 -> 3192.05 | W10: H2O | X10: =U10 -> 3192.05 | Y10: H2O | Z10: =X10-Y14 -> 1893.3691 | AB10: H2O | AC10: =Z10 -> 1893.3691 | AD10: H2O | AE10: =AC10-AD14 -> 594.68825 | AG10: H2O | AH10: =AE10 -> 594.68825 | AI10: H2O | AJ10: =AH10 -> 594.68825 | AL10: H2O | AM10: =AJ10 -> 594.68825 | AN10: CO2 | AO10: =0 -> 0 | BB10: =BB9*BE10 -> 670.75996 | BD10: inert percentage | BE10: =BE6/(BE6+BE5+BE4) -> 0.022339701
Y11: CO2 | Z11: =Y14 -> 1298.6809 | AB11: CO2 | AC11: =Z11 -> 1298.6809 | AD11: KHCO3 | AE11: =2*AD14 -> 2597.3617 | AG11: CO2 | AH11: =0 -> 0 | AI11: CO | AJ11: =0 -> 0 | AW11: e | AX11: =(AY7-0)/2 -> 1470.5882 | BB11: =1-BE10 -> 0.9776603
AB12: K2CO3 | AC12: =AD14 -> 1298.6809 | AD12: CO2 | AE12: 0
F13: e | G13: =(H5-0)/1 -> 42.923196 | K13: e | L13: =(M4-K5)/-1 -> 971.5
S14: e | T14: =(U7-S7)/-1 -> 395.5325 | X14: e | Y14: =(Z9-X9)/-1 -> 1298.6809 | AC14: e | AD14: =(AE12-AC11)/-1 -> 1298.6809 | AH14: e | AI14: =(0-AH9)/-2 -> 34.175813
AZ15: `

Sheet ENERGY BALANCE
F1: DESULPURISATION
T2: PREHEATER | U2: (After De Sulpurisation)
U3: c | V3: K
A4: NATURAL GAS | C4: DESULPHARISATION | T4: Tin | U4: 300 | V4: =U4+273.15 -> 573.15
A5: =25+273.15 -> 298.15 | B5: =A5-273.15 -> 25 | C5: =300+273.15 -> 573.15 | D5: =C5-273.15 -> 300 | T5: Tout | U5: 850 | V5: =U5+273.15 -> 1123.15
E6: 1 | F6: T | G6: T^2 | H6: T^-2 | J6: R | K6: 8.314
C7: delHr | E7: A | F7: B | G7: C | H7: D | U7: Cp | V7: A | W7: B | X7: C | Y7: D
C8: =-78 -> -78 | F8: =0.001 -> 0.001 | G8: =0.000001 -> 1e-06 | H8: =100000 -> 100000 | V8: 1 | W8: =0.001 -> 0.001 | X8: =0.000001 -> 1e-06 | Y8: =100000 -> 100000
A9: CH4 | B9: =('MATERIAL BALANCE'!F4)/(60*60*24) -> 0.016063079 | E9: 1.702 | F9: 9.081 | G9: -2.164 | H9: 0 | J9: =E9*($B$18-$B$19) -> -468.05 | K9: =(F9*$F$8*($B$18^2-B$19^2))*(1/2) -> -1087.9379 | L9: =(1/3)*G9*$G$8*($B$18^3-$B$19^3) -> 116.69495 | M9: =H9*$H$8*(1/$B$18-1/$B$19) -> 0 | O9: =SUM(J9:M9) -> -1439.2929 | P9: =O9*B9*$K$6 -> -192.21532 | T9: CH4 | V9: 1.702 | W9: 9.081 | X9: -2.164 | Y9: 0 | AA9: =V9*($V$5-$V$4) -> 936.1 | AB9: =(W9*$W$8*($V$5^2-$V$4^2))*(1/2) -> 4236.1276 | AC9: =(1/3)*X9*$X$8*($V$5^3-$V$4^3) -> -886.18335 | AD9: =Y9*$Y$8*(1/$V$5-1/$V$4) -> 0 | AF9: =SUM(AA9:AD9) -> 4286.0442 | AG9: =1387.9/(60*60*24) -> 0.016063657 | AH9: =AF9*AG9*8.314 -> 572.41513
A10: H2S | B10: =('MATERIAL BALANCE'!F5)/(60*60*24) -> 0.00049679625 | E10: 3.931 | F10: 1.49 | G10: 0 | H10: -0.232 | J10: =E10*($B$18-$B$19) -> -1081.025 | K10: =(F10*$F$8*($B$18^2-B$19^2))*(1/2) -> -178.50759 | L10: =(1/3)*G10*$G$8*($B$18^3-$B$19^3) -> 0 | M10: =H10*$H$8*(1/$B$18-1/$B$19) -> -37.335121 | O10: =SUM(J10:M10) -> -1296.8677 | P10: =O10*B10*$K$6 -> -5.3565357 | T10: H2S | V10: 3.931 | W10: 1.49 | X10: 0 | Y10: -0.232 | AA10: =V10*($V$5-$V$4) -> 2162.05 | AB10: =(W10*$W$8*($V$5^2-$V$4^2))*(1/2) -> 695.05893 | AC10: =(1/3)*X10*$X$8*($V$5^3-$V$4^3) -> 0 | AD10: =Y10*$Y$8*(1/$V$5-1/$V$4) -> 19.82187 | AF10: =SUM(AA10:AD10) -> 2876.9308 | AG10: ='MATERIAL BALANCE'!C5/(60*60*24) -> 0.00049679625 | AH10: =AF10*AG10*8.314 -> 11.882771 | AI10: =SUM(AH9:AH10) -> 584.2979 | AJ10: DH
A11: ZnO | B11: =('MATERIAL BALANCE'!F6)/(60*60*24) -> 0.00049679625 | E11: 45.91 | F11: 9.089 | G11: 4.159 | H11: -6.04976 | J11: =E11*($B$18-$B$19) -> -12625.25 | K11: =(F11*$F$8*($B$18^2-B$19^2))*(1/2) -> -1088.8963 | L11: =(1/3)*G11*$G$8*($B$18^3-$B$19^3) -> -224.27647 | M11: =H11*$H$8*(1/$B$18-1/$B$19) -> -973.57123 | O11: =SUM(J11:M11) -> -14911.994 | P11: =O11*B11*$K$6 -> -61.591963 | Q11: =SUM(P9:P11) -> -259.16382
T13: PREHEATER | U13: (Before Secondry Reformer)
A14: H2O | B14: =('MATERIAL BALANCE'!H4)/(60*60*24) -> 0.00049679625 | E14: 3.47 | F14: 1.45 | G14: 0 | H14: 0.121 | J14: =E14*($B$18-$B$19) -> -954.25 | K14: =(F14*$F$8*($B$18^2-B$19^2))*(1/2) -> -173.71544 | L14: =(1/3)*G14*$G$8*($B$18^3-$B$19^3) -> 0 | M14: =H14*$H$8*(1/$B$18-1/$B$19) -> 19.472197 | O14: =SUM(J14:M14) -> -1108.4932 | P14: =O14*B14*$K$6 -> -4.5784806
A15: ZnS | B15: =('MATERIAL BALANCE'!H5)/(60*60*24) -> 0.00049679625 | E15: 43.11 | F15: =0.012658*1000 -> 12.658 | G15: =-1.122 -> -1.122 | H15: =2.48 -> 2.48 | J15: =E15*($B$18-$B$19) -> -11855.25 | K15: =(F15*$F$8*($B$18^2-B$19^2))*(1/2) -> -1516.4759 | L15: =(1/3)*G15*$G$8*($B$18^3-$B$19^3) -> 60.504497 | M15: =H15*$H$8*(1/$B$18-1/$B$19) -> 399.09957 | O15: =SUM(J15:M15) -> -12912.122 | P15: =O15*B15*$K$6 -> -53.331763 | T15: Tin | U15: 25 | V15: 298.15
A16: CH4 | B16: =('MATERIAL BALANCE'!H6)/(60*60*24) -> 0.016063079 | E16: 1.702 | F16: 9.081 | G16: -2.164 | H16: 0 | J16: =E16*($B$18-$B$19) -> -468.05 | K16: =(F16*$F$8*($B$18^2-B$19^2))*(1/2) -> -1087.9379 | L16: =(1/3)*G16*$G$8*($B$18^3-$B$19^3) -> 116.69495 | M16: =H16*$H$8*(1/$B$18-1/$B$19) -> 0 | O16: =SUM(J16:M16) -> -1439.2929 | P16: =O16*B16*$K$6 -> -192.21532 | Q16: =SUM(P14:P16) -> -250.12556 | T16: Tout | U16: 500 | V16: =273.15+U16 -> 773.15
A18: Tin | B18: 298.15 | U18: Cp | V18: A | W18: B | X18: C | Y18: D
A19: Tout | B19: 573.15 | P19: DH | Q19: =(Q16+Q11)+('MATERIAL BALANCE'!G13*C8*1000/(24*60*60)) -> -548.03948 | V19: 1 | W19: =0.001 -> 0.001 | X19: =0.000001 -> 1e-06 | Y19: =100000 -> 100000
T20: O2 | V20: 3.639 | W20: 0.506 | X20: 0 | Y20: -0.227 | AA20: =V20*($V$16-$V$15) -> 1728.525 | AB20: =(W20*$W$8*($V$16^2-$V$15^2))*(1/2) -> 128.74348 | AC20: =(1/3)*X20*$X$8*($V$16^3-$V$15^3) -> 0 | AD20: =Y20*$Y$8*(1/$V$16-1/$V$15) -> 46.775764 | AF20: =SUM(AA20:AD20) -> 1904.0442 | AG20: ='MATERIAL BALANCE'!P5/(60*60*24) -> 0.0051978989 | AH20: =AF20*AG20*8.314 -> 82.283902
T21: N2 | V21: 3.28 | W21: 0.593 | X21: 0 | Y21: 0.04 | AA21: =V21*($V$16-$V$15) -> 1558 | AB21: =(W21*$W$8*($V$16^2-$V$15^2))*(1/2) -> 150.87921 | AC21: =(1/3)*X21*$X$8*($V$16^3-$V$15^3) -> 0 | AD21: =Y21*$Y$8*(1/$V$16-1/$V$15) -> -8.2424254 | AF21: =SUM(AA21:AD21) -> 1700.6368 | AG21: ='MATERIAL BALANCE'!P4/(60*60*24) -> 0.019306481 | AH21: =AF21*AG21*8.314 -> 272.97616
A22: rT | B22: 298.15 | F22: PRIMARY REFORMER | T22: INERT | V22: 20.786 | W22: 0.123 | X22: =-0.136 -> -0.136 | Y22: 0 | AA22: =V22*($V$16-$V$15) -> 9873.35 | AB22: =(W22*$W$8*($V$16^2-$V$15^2))*(1/2) -> 31.295351 | AC22: =(1/3)*X22*$X$8*($V$16^3-$V$15^3) -> -19.749706 | AD22: =Y22*$Y$8*(1/$V$16-1/$V$15) -> 0 | AF22: =SUM(AA22:AD22) -> 9884.8956 | AG22: ='MATERIAL BALANCE'!P6/(60*60*24) -> 0.00022662037 | AH22: =AF22*AG22*8.314 -> 18.624347 | AI22: =SUM(AH20:AH22) -> 373.88441 | AJ22: DH
A24: INPUTS | D24: del Hr | E24: =206 -> 206 | T24: COOLER | U24: (Before Water gas shift reaction)
A26: Steam | B26: 400 | C26: =B26+273.15 -> 673.15 | T26: Tin | U26: 1000 | V26: =273.15+U26 -> 1273.15
A27: H2O | B27: =('MATERIAL BALANCE'!K4)/(60*60*24) -> 0.048189236 | E27: 3.47 | F27: 1.45 | G27: 0 | H27: 0.121 | J27: =E27*($B$22-$C26) -> -1301.25 | K27: =(F27*$F$8*($B$22^2-$C26^2))*(1/2) -> -264.07219 | L27: =(1/3)*G27*$G$8*($B$22^3-$C26^3) -> 0 | M27: =H27*$H$8*(1/$B$22-1/$C26) -> 22.608408 | O27: =SUM(J27:M27) -> -1542.7138 | P27: =O27*B27*$K$6 -> -618.08104 | T27: Tout | U27: 350 | V27: =273.15+U27 -> 623.15
B29: 850 | C29: =B29+273.15 -> 1123.15 | U29: Cp | V29: A | W29: B | X29: C | Y29: D
A30: CH4 | B30: =('MATERIAL BALANCE'!K5)/(60*60*24) -> 0.016063079 | E30: 1.702 | F30: 9.081 | G30: -2.164 | H30: 0 | J30: =E30*($B$22-$C29) -> -1404.15 | K30: =(F30*$F$8*($B$22^2-$C29^2))*(1/2) -> -5324.0654 | L30: =(1/3)*G30*$G$8*($B$22^3-$C29^3) -> 1002.8783 | M30: =H30*$H$8*(1/$B$22-1/$C29) -> 0 | O30: =SUM(J30:M30) -> -5725.3371 | P30: =O30*B30*$K$6 -> -764.60982 | Q30: =SUM(P27:P30) -> -1382.6909 | V30: 1 | W30: =0.001 -> 0.001 | X30: =0.000001 -> 1e-06 | Y30: =100000 -> 100000
T31: N2 | V31: 3.28 | W31: 0.593 | X31: 0 | Y31: 0.04 | AA31: =V31*($V$27-$V$26) -> -2132 | AB31: =(W31*$W$8*($V$27^2-$V$26^2))*(1/2) -> -365.46442 | AC31: =(1/3)*X31*$X$8*($V$27^3-$V$26^3) -> 0 | AD31: =Y31*$Y$8*(1/$V$27-1/$V$26) -> 3.2771866 | AF31: =SUM(AA31:AD31) -> -2494.1872 | AG31: ='MATERIAL BALANCE'!U4/(60*60*24) -> 0.019306481 | AH31: =AF31*AG31*8.314 -> -400.35219
A32: OUTPUTS | T32: O2 | V32: 3.639 | W32: 0.506 | X32: 0 | Y32: -0.227 | AA32: =V32*($V$27-$V$26) -> -2365.35 | AB32: =(W32*$W$8*($V$27^2-$V$26^2))*(1/2) -> -311.84654 | AC32: =(1/3)*X32*$X$8*($V$27^3-$V$26^3) -> 0 | AD32: =Y32*$Y$8*(1/$V$27-1/$V$26) -> -18.598034 | AF32: =SUM(AA32:AD32) -> -2695.7946 | AG32: ='MATERIAL BALANCE'!U5/(60*60*24) -> 0.0029089376 | AH32: =AF32*AG32*8.314 -> -65.197542
T33: CH4 | V33: 1.702 | W33: 9.081 | X33: -2.164 | Y33: 0 | AA33: =V33*($V$27-$V$26) -> -1106.3 | AB33: =(W33*$W$8*($V$27^2-$V$26^2))*(1/2) -> -5596.5976 | AC33: =(1/3)*X33*$X$8*($V$27^3-$V$26^3) -> 1314.0412 | AD33: =Y33*$Y$8*(1/$V$27-1/$V$26) -> 0 | AF33: =SUM(AA33:AD33) -> -5388.8564 | AG33: ='MATERIAL BALANCE'!U7/(60*60*24) -> 0.00024094329 | AH33: =AF33*AG33*8.314 -> -10.794971
A34: PR T | B34: 900 | C34: =273.15+B34 -> 1173.15 | T34: H2 | V34: 3.249 | W34: 0.422 | X34: 0 | Y34: 0.083 | AA34: =V34*($V$27-$V$26) -> -2111.85 | AB34: =(W34*$W$8*($V$27^2-$V$26^2))*(1/2) -> -260.07755 | AC34: =(1/3)*X34*$X$8*($V$27^3-$V$26^3) -> 0 | AD34: =Y34*$Y$8*(1/$V$27-1/$V$26) -> 6.8001623 | AF34: =SUM(AA34:AD34) -> -2365.1274 | AG34: ='MATERIAL BALANCE'!U8/(60*60*24) -> 0.042888484 | AH34: =AF34*AG34*8.314 -> -843.34495
A35: CH4 | B35: =('MATERIAL BALANCE'!M4)/(60*60*24) -> 0.0048188657 | E35: 1.702 | F35: 9.081 | G35: -2.164 | H35: 0 | J35: =-E35*($B$22-$C34) -> 1489.25 | K35: =-1*(F35*$F$8*($B$22^2-$C34^2))*(1/2) -> 5845.3829 | L35: =-1*(1/3)*G35*$G$8*($B$22^3-$C$34^3) -> -1145.5353 | M35: =-1*H35*$H$8*(1/$B$22-1/$C$34) -> 0 | O35: =SUM(J35:M35) -> 6189.0976 | P35: =O35*B35*$K$6 -> 247.96032 | T35: CO | V35: 3.376 | W35: 0.557 | X35: 0 | Y35: -0.031 | AA35: =V35*($V$27-$V$26) -> -2194.4 | AB35: =(W35*$W$8*($V$27^2-$V$26^2))*(1/2) -> -343.27771 | AC35: =(1/3)*X35*$X$8*($V$27^3-$V$26^3) -> 0 | AD35: =Y35*$Y$8*(1/$V$27-1/$V$26) -> -2.5398196 | AF35: =SUM(AA35:AD35) -> -2540.2175 | AG35: ='MATERIAL BALANCE'!U9/(60*60*24) -> 0.015822135 | AH35: =AF35*AG35*8.314 -> -334.15351
A36: CO | B36: =('MATERIAL BALANCE'!M5)/(60*60*24) -> 0.011244213 | E36: 3.376 | F36: 0.557 | G36: 0 | H36: -0.031 | J36: =-E36*($B$22-$C34) -> 2954 | K36: =-1*(F36*$F$8*($B$22^2-$C34^2))*(1/2) -> 358.53742 | L36: =-1*(1/3)*G36*$G$8*($B$22^3-$C$34^3) -> 0 | M36: =-1*H36*$H$8*(1/$B$22-1/$C$34) -> 7.7549926 | O36: =SUM(J36:M36) -> 3320.2924 | P36: =O36*B36*$K$6 -> 310.3955 | T36: H2O | V36: 3.47 | W36: 1.45 | X36: 0 | Y36: 0.121 | AA36: =V36*($V$27-$V$26) -> -2255.5 | AB36: =(W36*$W$8*($V$27^2-$V$26^2))*(1/2) -> -893.63138 | AC36: =(1/3)*X36*$X$8*($V$27^3-$V$26^3) -> 0 | AD36: =Y36*$Y$8*(1/$V$27-1/$V$26) -> 9.9134896 | AF36: =SUM(AA36:AD36) -> -3139.2179 | AG36: ='MATERIAL BALANCE'!U10/(60*60*24) -> 0.036945023 | AH36: =AF36*AG36*8.314 -> -964.24506
A37: H2 | B37: =('MATERIAL BALANCE'!M6)/(60*60*24) -> 0.033732639 | E37: 3.249 | F37: 0.422 | G37: 0 | H37: 0.083 | J37: =-E37*($B$22-$C34) -> 2842.875 | K37: =-1*(F37*$F$8*($B$22^2-$C34^2))*(1/2) -> 271.63876 | L37: =-1*(1/3)*G37*$G$8*($B$22^3-$C$34^3) -> 0 | M37: =-1*H37*$H$8*(1/$B$22-1/$C$34) -> -20.763367 | O37: =SUM(J37:M37) -> 3093.7504 | P37: =O37*B37*$K$6 -> 867.65207 | T37: INERT | V37: 20.786 | W37: 0.123 | X37: =-0.136 -> -0.136 | Y37: 0 | AA37: =V37*($V$27-$V$26) -> -13510.9 | AB37: =(W37*$W$8*($V$27^2-$V$26^2))*(1/2) -> -75.804593 | AC37: =(1/3)*X37*$X$8*($V$27^3-$V$26^3) -> 82.582993 | AD37: =Y37*$Y$8*(1/$V$27-1/$V$26) -> 0 | AF37: =SUM(AA37:AD37) -> -13504.122 | AG37: ='MATERIAL BALANCE'!U6/(60*60*24) -> 0.00022662037 | AH37: =AF37*AG37*8.314 -> -25.443409 | AI37: =SUM(AH31:AH37) -> -2643.5316 | AJ37: DH
A38: H2O | B38: =('MATERIAL BALANCE'!M7)/(60*60*24) -> 0.036945023 | E38: 3.47 | F38: 1.45 | G38: 0 | H38: 0.121 | J38: =-E38*($B$22-$C34) -> 3036.25 | K38: =-1*(F38*$F$8*($B$22^2-$C34^2))*(1/2) -> 933.35594 | L38: =-1*(1/3)*G38*$G$8*($B$22^3-$C$34^3) -> 0 | M38: =-1*H38*$H$8*(1/$B$22-1/$C$34) -> -30.269487 | O38: =SUM(J38:M38) -> 3939.3365 | P38: =O38*B38*$K$6 -> 1210.0102 | Q38: =SUM(P35:P38) -> 2636.0181
T39: COOLER | U39: (Before CO2 removal)
P40: DH | Q40: =(Q38+Q30)+('MATERIAL BALANCE'!L13*('ENERGY BALANCE'!E24)*1000/(60*60*24)) -> 3569.6351
F41: SECONDRYREFORMER | T41: Tin | U41: 350 | V41: =273.15+U41 -> 623.15
A42: INPUTS | T42: Tout | U42: 110 | V42: =273.15+U42 -> 383.15
D43: del Hr | E43: =-36 -> -36
B44: 900 | C44: =273.15+B44 -> 1173.15 | U44: Cp | V44: A | W44: B | X44: C | Y44: D
A45: CH4 | B45: =('MATERIAL BALANCE'!S7)/(24*60*60) -> 0.0048188657 | E45: 1.702 | F45: 9.081 | G45: -2.164 | H45: 0 | J45: =E45*($B$22-$C44) -> -1489.25 | K45: =(F45*$F$8*($B$22^2-$C$44^2))*(1/2) -> -5845.3829 | L45: =(1/3)*G45*$G$8*($B$22^3-$C$44^3) -> 1145.5353 | M45: =H45*$H$8*(1/$B$22-1/$C$44) -> 0 | O45: =SUM(J45:M45) -> -6189.0976 | P45: =O45*B45*$K$6 -> -247.96032 | V45: 1 | W45: =0.001 -> 0.001 | X45: =0.000001 -> 1e-06 | Y45: =100000 -> 100000
...

Sheet fluids
B1: (NATURAL GAS-DESULFURISATION) | N1: AIR - COMPRESSOR
B2: Natural gas | N2: air
B3: P | C3: 25 | D3: =C3*1.013*10^5 -> 2532500 | N3: P | O3: 1 | P3: =O3*1.013*10^5 -> 101300
B4: T | C4: 300 | D4: =C4+273.15 -> 573.15 | N4: T | O4: 25 | P4: =O4+273.15 -> 298.15
B5: R | C5: 8.314 | D5: 8.314 | N5: R | O5: 8.314 | P5: 8.314
C7: KMOL/DAY | D7: mol/sec | E7: density | F7: viscosity | G7: mole fraction | O7: KMOL/DAY | P7: mol/sec | Q7: density | R7: viscosity | S7: mole fraction
B8: CH4 | C8: 1387.9 | D8: =(C8*1000)/(24*60*60) -> 16.063657 | E8: =10.12 -> 10.12 | F8: =18.6*10^-6 -> 1.86e-05 | G8: =D8/D11 -> 0.97001677 | J8: flow rate | K8: =(D11*D5*D4)/D3 -> 0.031159756 | N8: AIR | O8: 2138.6 | P8: =(O8*1000)/(24*60*60) -> 24.752315 | Q8: 1.18 | R8: =18.6*10^-6 -> 1.86e-05 | S8: =P8/P11 -> 1 | U8: flow rate | V8: =(P11*P5*P4)/P3 -> 0.60569112
B9: H2S | C9: 42.9 | D9: =(C9*1000)/(24*60*60) -> 0.49652778 | E9: =22.19 -> 22.19 | F9: =16.9*10^-6 -> 1.69e-05 | G9: =D9/D11 -> 0.029983226
J10: carbon steel | U10: carbon steel
C11: mixture | D11: =SUM(D8:D9) -> 16.560185 | E11: =(E8*G8)+(E9*G9) -> 10.481898 | F11: =(G8*F8)+(G9*F9) -> 1.8549029e-05 | G11: =SUM(G8:G9) -> 1 | J11: NPS-2 | O11: mixture | P11: =SUM(P8:P9) -> 24.752315 | Q11: =(Q8*S8)+(Q9*S9) -> 1.18 | R11: =(S8*R8)+(S9*R9) -> 1.86e-05 | S11: =SUM(S8:S9) -> 1 | U11: NPS-2
J12: ID(mm) | K12: =52.5 -> 52.5 | U12: ID(mm) | V12: =P17 -> 311.2
J13: velocity | K13: =D14 -> 14.394135 | U13: velocity | V13: =P14 -> 7.9630996
B14: velocity | C14: 10 | D14: =K8/D15 -> 14.394135 | F14: Re | G14: =(E11*D14*D16)/F11 -> 427035.13 | J14: thickness(mm) | K14: =(K15-K12)/2 -> 3.9 | N14: velocity | O14: 8 | P14: =V8/P15 -> 7.9630996 | R14: Re | S14: =(Q11*P14*P16)/R11 -> 157213.85 | U14: thickness(mm) | V14: =(V15-V12)/2 -> 6.35
B15: Area | C15: =K8/C14 -> 0.0031159756 | D15: =PI()*D16*D16/4 -> 0.0021647537 | F15: f | G15: 0.02 | J15: OD | K15: =60.3 -> 60.3 | N15: Area | O15: =V8/O14 -> 0.07571139 | P15: =PI()*P16*P16/4 -> 0.076062231 | R15: f | S15: 0.0159 | U15: OD | V15: 323.9
B16: diameter(m) | C16: =((4*C15)/PI())^0.5 -> 0.062987168 | D16: =D17/1000 -> 0.0525 | F16: length | G16: 5 | J16: f friction factor | K16: =G15 -> 0.02 | N16: diameter(m) | O16: =((4*O15)/PI())^0.5 -> 0.31048146 | P16: =P17/1000 -> 0.3112 | R16: length | S16: 8 | U16: f friction factor | V16: =S15 -> 0.0159
B17: diameter(mm) | C17: =C16*1000 -> 62.987168 | D17: 52.5 | F17: del P | G17: =G15*G16*E11*D14*D14/(2*D16) -> 2068.3391 | J17: del P(bar) | K17: =G17/(1.01321*10^5) -> 0.020413726 | N17: diameter(mm) | O17: =O16*1000 -> 310.48146 | P17: 311.2 | R17: del P | S17: =S15*S16*Q11*P14*P14/(2*P16) -> 15.291984 | U17: del P(bar) | V17: =S17/(1.01321*10^5) -> 0.00015092611
B18: diameter(inch) | C18: =C17/25.4 -> 2.4798098 | J18: botttom to bottom | N18: diameter(inch) | O18: =O17/25.4 -> 12.223679 | U18: top to side
J19: length(m) | K19: 5 | U19: length(m) | V19: 5
B21: DESULFURISATION-PREHEATER | N21: COMPRESSOR-PREHEATER
B22: DESULFURISATION | N22: compressor
B23: P | C23: 25 | D23: =C23*1.013*10^5 -> 2532500 | N23: P | O23: 25 | P23: =O23*1.013*10^5 -> 2532500
B24: T | C24: 300 | D24: =C24+273.15 -> 573.15 | N24: T | O24: 475 | P24: =O24+273.15 -> 748.15
B25: R | C25: 8.314 | D25: 8.314 | N25: R | O25: 8.314 | P25: 8.314
C27: KMOL/DAY | D27: mol/sec | E27: density | F27: viscosity | G27: mole fraction | O27: KMOL/DAY | P27: mol/sec | Q27: density | R27: viscosity | S27: mole fraction
B28: CH4 | C28: 1387.9 | D28: =(C28*1000)/(24*60*60) -> 16.063657 | E28: =10.12 -> 10.12 | F28: =18.6*10^-6 -> 1.86e-05 | G28: =D28/D31 -> 1 | J28: flow rate | K28: =(D31*D25*D24)/D23 -> 0.030225486 | N28: AIR | O28: 2138.6 | P28: =(O28*1000)/(24*60*60) -> 24.752315 | Q28: 12.1 | R28: =36*10^-6 -> 3.6e-05 | S28: =P28/P31 -> 1 | U28: flow rate | V28: =(P31*P25*P24)/P23 -> 0.060794609
J30: carbon steel | U30: stainless steel
C31: mixture | D31: =SUM(D28:D29) -> 16.063657 | E31: =(E28*G28)+(E29*G29) -> 10.12 | F31: =(G28*F28)+(G29*F29) -> 1.86e-05 | G31: =SUM(G28:G29) -> 1 | J31: NPS-2 | O31: mixture | P31: =SUM(P28:P29) -> 24.752315 | Q31: =(Q28*S28)+(Q29*S29) -> 12.1 | R31: =(S28*R28)+(S29*R29) -> 3.6e-05 | S31: =SUM(S28:S29) -> 1 | U31: DN80
J32: ID(mm) | K32: =52.5 -> 52.5 | U32: ID(mm) | V32: =P37 -> 78
J33: velocity | K33: =D34 -> 13.962552 | U33: velocity | V33: =P34 -> 12.722896
B34: velocity | C34: 10 | D34: =K28/D35 -> 13.962552 | F34: Re | G34: =(E31*D34*D36)/F31 -> 398833.55 | J34: thickness(mm) | K34: =(K35-K32)/2 -> 3.9 | N34: velocity | O34: 15 | P34: =V28/P35 -> 12.722896 | R34: Re | S34: =(Q31*P34*P36)/R31 -> 333551.93 | U34: thickness(mm) | V34: =(V35-V32)/2 -> 5.45
B35: Area | C35: =K28/C34 -> 0.0030225486 | D35: =PI()*D36*D36/4 -> 0.0021647537 | F35: f | G35: 0.02 | J35: OD | K35: =60.3 -> 60.3 | N35: Area | O35: =V28/O34 -> 0.0040529739 | P35: =PI()*P36*P36/4 -> 0.0047783624 | R35: f | S35: 0.0165 | U35: OD | V35: 88.9
B36: diameter(m) | C36: =((4*C35)/PI())^0.5 -> 0.062035703 | D36: =D37/1000 -> 0.0525 | F36: length | G36: 5 | J36: f friction factor | K36: =G35 -> 0.02 | N36: diameter(m) | O36: =((4*O35)/PI())^0.5 -> 0.07183597 | P36: =P37/1000 -> 0.078 | R36: length | S36: 0.7 | U36: f friction factor | V36: =S35 -> 0.0165
B37: diameter(mm) | C37: =C36*1000 -> 62.035703 | D37: 52.5 | F37: del P | G37: =G35*G36*E31*D34*D34/(2*D36) -> 1878.9743 | J37: del P(bar) | K37: =G37/(1.01321*10^5) -> 0.018544766 | N37: diameter(mm) | O37: =O36*1000 -> 71.83597 | P37: 78 | R37: del P | S37: =S35*S36*Q31*P34*P34/(2*P36) -> 145.0156 | U37: del P(bar) | V37: =S37/(1.01321*10^5) -> 0.0014312492
B38: diameter(inch) | C38: =C37/25.4 -> 2.4423505 | J38: botttom to bottom | N38: diameter(inch) | O38: =O37/25.4 -> 2.8281878 | U38: side to bottom
J39: length(m) | K39: 5 | U39: length(m) | V39: 5
B41: PREHEATER-PRIMARY REFORMER | N41: STEAM SUPPLY-PRIMARY REFORMER
B42: prerheater | N42: steam supply
B43: P | C43: 25 | D43: =C43*1.013*10^5 -> 2532500 | N43: P | O43: 25 | P43: =O43*1.013*10^5 -> 2532500
B44: T | C44: 850 | D44: =C44+273.15 -> 1123.15 | N44: T | O44: 400 | P44: =O44+273.15 -> 673.15
B45: R | C45: 8.314 | D45: 8.314 | N45: R | O45: 8.314 | P45: 8.314
...

Sheet HEAT TRANSFER
F1: DESULPURISATION
T2: PREHEATER | U2: (After De Sulpurisation)
U3: c | V3: K
A4: NATURAL GAS | C4: DESULPHARISATION | T4: Tin | U4: 300 | V4: =U4+273.15 -> 573.15
A5: =25+273.15 -> 298.15 | B5: =A5-273.15 -> 25 | C5: =300+273.15 -> 573.15 | D5: =C5-273.15 -> 300 | T5: Tout | U5: 850 | V5: =U5+273.15 -> 1123.15
E6: 1 | F6: T | G6: T^2 | H6: T^-2 | J6: R | K6: 8.314
C7: delHr | E7: A | F7: B | G7: C | H7: D | U7: Cp | V7: A | W7: B | X7: C | Y7: D
C8: =-78 -> -78 | F8: =0.001 -> 0.001 | G8: =0.000001 -> 1e-06 | H8: =100000 -> 100000 | V8: 1 | W8: =0.001 -> 0.001 | X8: =0.000001 -> 1e-06 | Y8: =100000 -> 100000
A9: CH4 | B9: =('MATERIAL BALANCE'!F4)/(60*60*24) -> 0.016063079 | E9: 1.702 | F9: 9.081 | G9: -2.164 | H9: 0 | J9: =E9*($B$18-$B$19) -> 0 | K9: =(F9*$F$8*($B$18^2-B$19^2))*(1/2) -> 0 | L9: =(1/3)*G9*$G$8*($B$18^3-$B$19^3) -> 0 | M9: =H9*$H$8*(1/$B$18-1/$B$19) -> 0 | O9: =SUM(J9:M9) -> 0 | P9: =O9*B9*$K$6 -> 0 | T9: CH4 | V9: 1.702 | W9: 9.081 | X9: -2.164 | Y9: 0 | AA9: =V9*($V$5-$V$4) -> 936.1 | AB9: =(W9*$W$8*($V$5^2-$V$4^2))*(1/2) -> 4236.1276 | AC9: =(1/3)*X9*$X$8*($V$5^3-$V$4^3) -> -886.18335 | AD9: =Y9*$Y$8*(1/$V$5-1/$V$4) -> 0 | AF9: =SUM(AA9:AD9) -> 4286.0442 | AG9: =1387.9/(60*60*24) -> 0.016063657 | AH9: =AF9*AG9*8.314 -> 572.41513
A10: H2S | B10: =('MATERIAL BALANCE'!F5)/(60*60*24) -> 0.00049679625 | E10: 3.931 | F10: 1.49 | G10: 0 | H10: -0.232 | J10: =E10*($B$18-$B$19) -> 0 | K10: =(F10*$F$8*($B$18^2-B$19^2))*(1/2) -> 0 | L10: =(1/3)*G10*$G$8*($B$18^3-$B$19^3) -> 0 | M10: =H10*$H$8*(1/$B$18-1/$B$19) -> 0 | O10: =SUM(J10:M10) -> 0 | P10: =O10*B10*$K$6 -> 0 | T10: H2S | V10: 3.931 | W10: 1.49 | X10: 0 | Y10: -0.232 | AA10: =V10*($V$5-$V$4) -> 2162.05 | AB10: =(W10*$W$8*($V$5^2-$V$4^2))*(1/2) -> 695.05893 | AC10: =(1/3)*X10*$X$8*($V$5^3-$V$4^3) -> 0 | AD10: =Y10*$Y$8*(1/$V$5-1/$V$4) -> 19.82187 | AF10: =SUM(AA10:AD10) -> 2876.9308 | AG10: ='MATERIAL BALANCE'!C5/(60*60*24) -> 0.00049679625 | AH10: =AF10*AG10*8.314 -> 11.882771 | AI10: =SUM(AH9:AH10) -> 584.2979 | AJ10: DH
A11: ZnO | B11: =('MATERIAL BALANCE'!F6)/(60*60*24) -> 0.00049679625 | E11: 45.91 | F11: 9.089 | G11: 4.159 | H11: -6.04976 | J11: =E11*($B$18-$B$19) -> 0 | K11: =(F11*$F$8*($B$18^2-B$19^2))*(1/2) -> 0 | L11: =(1/3)*G11*$G$8*($B$18^3-$B$19^3) -> 0 | M11: =H11*$H$8*(1/$B$18-1/$B$19) -> 0 | O11: =SUM(J11:M11) -> 0 | P11: =O11*B11*$K$6 -> 0 | Q11: =SUM(P9:P11) -> 0
T13: PREHEATER | U13: (Before Secondry Reformer)
A14: H2O | B14: =('MATERIAL BALANCE'!H4)/(60*60*24) -> 0.00049679625 | E14: 3.47 | F14: 1.45 | G14: 0 | H14: 0.121 | J14: =E14*($B$18-$B$19) -> 0 | K14: =(F14*$F$8*($B$18^2-B$19^2))*(1/2) -> 0 | L14: =(1/3)*G14*$G$8*($B$18^3-$B$19^3) -> 0 | M14: =H14*$H$8*(1/$B$18-1/$B$19) -> 0 | O14: =SUM(J14:M14) -> 0 | P14: =O14*B14*$K$6 -> 0
A15: ZnS | B15: =('MATERIAL BALANCE'!H5)/(60*60*24) -> 0.00049679625 | E15: 43.11 | F15: =0.012658*1000 -> 12.658 | G15: =-1.122 -> -1.122 | H15: =2.48 -> 2.48 | J15: =E15*($B$18-$B$19) -> 0 | K15: =(F15*$F$8*($B$18^2-B$19^2))*(1/2) -> 0 | L15: =(1/3)*G15*$G$8*($B$18^3-$B$19^3) -> 0 | M15: =H15*$H$8*(1/$B$18-1/$B$19) -> 0 | O15: =SUM(J15:M15) -> 0 | P15: =O15*B15*$K$6 -> 0 | T15: Tin | U15: 475 | V15: 298.15
A16: CH4 | B16: =('MATERIAL BALANCE'!H6)/(60*60*24) -> 0.016063079 | E16: 1.702 | F16: 9.081 | G16: -2.164 | H16: 0 | J16: =E16*($B$18-$B$19) -> 0 | K16: =(F16*$F$8*($B$18^2-B$19^2))*(1/2) -> 0 | L16: =(1/3)*G16*$G$8*($B$18^3-$B$19^3) -> 0 | M16: =H16*$H$8*(1/$B$18-1/$B$19) -> 0 | O16: =SUM(J16:M16) -> 0 | P16: =O16*B16*$K$6 -> 0 | Q16: =SUM(P14:P16) -> 0 | T16: Tout | U16: 1000 | V16: =273.15+U16 -> 1273.15
A18: Tin | B18: 573.15 | U18: Cp | V18: A | W18: B | X18: C | Y18: D
A19: Tout | B19: 573.15 | P19: DH | Q19: =(Q16+Q11)+('MATERIAL BALANCE'!G13*C8*1000/(24*60*60)) -> -38.750107 | V19: 1 | W19: =0.001 -> 0.001 | X19: =0.000001 -> 1e-06 | Y19: =100000 -> 100000
T20: O2 | V20: 3.639 | W20: 0.506 | X20: 0 | Y20: -0.227 | AA20: =V20*($V$16-$V$15) -> 3548.025 | AB20: =(W20*$W$8*($V$16^2-$V$15^2))*(1/2) -> 387.60043 | AC20: =(1/3)*X20*$X$8*($V$16^3-$V$15^3) -> 0 | AD20: =Y20*$Y$8*(1/$V$16-1/$V$15) -> 58.306381 | AF20: =SUM(AA20:AD20) -> 3993.9318 | AG20: ='MATERIAL BALANCE'!P5/(60*60*24) -> 0.0051978989 | AH20: =AF20*AG20*8.314 -> 172.59909
T21: N2 | V21: 3.28 | W21: 0.593 | X21: 0 | Y21: 0.04 | AA21: =V21*($V$16-$V$15) -> 3198 | AB21: =(W21*$W$8*($V$16^2-$V$15^2))*(1/2) -> 454.24319 | AC21: =(1/3)*X21*$X$8*($V$16^3-$V$15^3) -> 0 | AD21: =Y21*$Y$8*(1/$V$16-1/$V$15) -> -10.274252 | AF21: =SUM(AA21:AD21) -> 3641.9689 | AG21: ='MATERIAL BALANCE'!P4/(60*60*24) -> 0.019306481 | AH21: =AF21*AG21*8.314 -> 584.58732
A22: rT | B22: 298.15 | F22: PRIMARY REFORMER | T22: INERT | V22: 20.786 | W22: 0.123 | X22: =-0.136 -> -0.136 | Y22: 0 | AA22: =V22*($V$16-$V$15) -> 20266.35 | AB22: =(W22*$W$8*($V$16^2-$V$15^2))*(1/2) -> 94.219076 | AC22: =(1/3)*X22*$X$8*($V$16^3-$V$15^3) -> -92.351216 | AD22: =Y22*$Y$8*(1/$V$16-1/$V$15) -> 0 | AF22: =SUM(AA22:AD22) -> 20268.218 | AG22: ='MATERIAL BALANCE'!P6/(60*60*24) -> 0.00022662037 | AH22: =AF22*AG22*8.314 -> 38.18779 | AI22: =SUM(AH20:AH22) -> 795.37419 | AJ22: DH
A24: INPUTS | D24: del Hr | E24: =206 -> 206 | T24: COOLER | U24: (Before Water gas shift reaction)
A26: Steam | B26: 400 | C26: =B26+273.15 -> 673.15 | T26: Tin | U26: 1000 | V26: =273.15+U26 -> 1273.15
A27: H2O | B27: =('MATERIAL BALANCE'!K4)/(60*60*24) -> 0.048189236 | E27: 3.47 | F27: 1.45 | G27: 0 | H27: 0.121 | J27: =E27*($B$22-$C26) -> -1301.25 | K27: =(F27*$F$8*($B$22^2-$C26^2))*(1/2) -> -264.07219 | L27: =(1/3)*G27*$G$8*($B$22^3-$C26^3) -> 0 | M27: =H27*$H$8*(1/$B$22-1/$C26) -> 22.608408 | O27: =SUM(J27:M27) -> -1542.7138 | P27: =O27*B27*$K$6 -> -618.08104 | T27: Tout | U27: 350 | V27: =273.15+U27 -> 623.15
B29: 850 | C29: =B29+273.15 -> 1123.15 | U29: Cp | V29: A | W29: B | X29: C | Y29: D
A30: CH4 | B30: =('MATERIAL BALANCE'!K5)/(60*60*24) -> 0.016063079 | E30: 1.702 | F30: 9.081 | G30: -2.164 | H30: 0 | J30: =E30*($B$22-$C29) -> -1404.15 | K30: =(F30*$F$8*($B$22^2-$C29^2))*(1/2) -> -5324.0654 | L30: =(1/3)*G30*$G$8*($B$22^3-$C29^3) -> 1002.8783 | M30: =H30*$H$8*(1/$B$22-1/$C29) -> 0 | O30: =SUM(J30:M30) -> -5725.3371 | P30: =O30*B30*$K$6 -> -764.60982 | Q30: =SUM(P27:P30) -> -1382.6909 | V30: 1 | W30: =0.001 -> 0.001 | X30: =0.000001 -> 1e-06 | Y30: =100000 -> 100000
T31: N2 | V31: 3.28 | W31: 0.593 | X31: 0 | Y31: 0.04 | AA31: =V31*($V$27-$V$26) -> -2132 | AB31: =(W31*$W$8*($V$27^2-$V$26^2))*(1/2) -> -365.46442 | AC31: =(1/3)*X31*$X$8*($V$27^3-$V$26^3) -> 0 | AD31: =Y31*$Y$8*(1/$V$27-1/$V$26) -> 3.2771866 | AF31: =SUM(AA31:AD31) -> -2494.1872 | AG31: ='MATERIAL BALANCE'!U4/(60*60*24) -> 0.019306481 | AH31: =AF31*AG31*8.314 -> -400.35219
A32: OUTPUTS | T32: O2 | V32: 3.639 | W32: 0.506 | X32: 0 | Y32: -0.227 | AA32: =V32*($V$27-$V$26) -> -2365.35 | AB32: =(W32*$W$8*($V$27^2-$V$26^2))*(1/2) -> -311.84654 | AC32: =(1/3)*X32*$X$8*($V$27^3-$V$26^3) -> 0 | AD32: =Y32*$Y$8*(1/$V$27-1/$V$26) -> -18.598034 | AF32: =SUM(AA32:AD32) -> -2695.7946 | AG32: ='MATERIAL BALANCE'!U5/(60*60*24) -> 0.0029089376 | AH32: =AF32*AG32*8.314 -> -65.197542
T33: CH4 | V33: 1.702 | W33: 9.081 | X33: -2.164 | Y33: 0 | AA33: =V33*($V$27-$V$26) -> -1106.3 | AB33: =(W33*$W$8*($V$27^2-$V$26^2))*(1/2) -> -5596.5976 | AC33: =(1/3)*X33*$X$8*($V$27^3-$V$26^3) -> 1314.0412 | AD33: =Y33*$Y$8*(1/$V$27-1/$V$26) -> 0 | AF33: =SUM(AA33:AD33) -> -5388.8564 | AG33: ='MATERIAL BALANCE'!U7/(60*60*24) -> 0.00024094329 | AH33: =AF33*AG33*8.314 -> -10.794971
A34: PR T | B34: 850 | C34: =273.15+B34 -> 1123.15 | T34: H2 | V34: 3.249 | W34: 0.422 | X34: 0 | Y34: 0.083 | AA34: =V34*($V$27-$V$26) -> -2111.85 | AB34: =(W34*$W$8*($V$27^2-$V$26^2))*(1/2) -> -260.07755 | AC34: =(1/3)*X34*$X$8*($V$27^3-$V$26^3) -> 0 | AD34: =Y34*$Y$8*(1/$V$27-1/$V$26) -> 6.8001623 | AF34: =SUM(AA34:AD34) -> -2365.1274 | AG34: ='MATERIAL BALANCE'!U8/(60*60*24) -> 0.042888484 | AH34: =AF34*AG34*8.314 -> -843.34495
A35: CH4 | B35: =('MATERIAL BALANCE'!M4)/(60*60*24) -> 0.0048188657 | E35: 1.702 | F35: 9.081 | G35: -2.164 | H35: 0 | J35: =-E35*($B$22-$C34) -> 1404.15 | K35: =-1*(F35*$F$8*($B$22^2-$C34^2))*(1/2) -> 5324.0654 | L35: =-1*(1/3)*G35*$G$8*($B$22^3-$C$34^3) -> -1002.8783 | M35: =-1*H35*$H$8*(1/$B$22-1/$C$34) -> 0 | O35: =SUM(J35:M35) -> 5725.3371 | P35: =O35*B35*$K$6 -> 229.38019 | T35: CO | V35: 3.376 | W35: 0.557 | X35: 0 | Y35: -0.031 | AA35: =V35*($V$27-$V$26) -> -2194.4 | AB35: =(W35*$W$8*($V$27^2-$V$26^2))*(1/2) -> -343.27771 | AC35: =(1/3)*X35*$X$8*($V$27^3-$V$26^3) -> 0 | AD35: =Y35*$Y$8*(1/$V$27-1/$V$26) -> -2.5398196 | AF35: =SUM(AA35:AD35) -> -2540.2175 | AG35: ='MATERIAL BALANCE'!U9/(60*60*24) -> 0.015822135 | AH35: =AF35*AG35*8.314 -> -334.15351
A36: CO | B36: =('MATERIAL BALANCE'!M5)/(60*60*24) -> 0.011244213 | E36: 3.376 | F36: 0.557 | G36: 0 | H36: -0.031 | J36: =-E36*($B$22-$C34) -> 2785.2 | K36: =-1*(F36*$F$8*($B$22^2-$C34^2))*(1/2) -> 326.56144 | L36: =-1*(1/3)*G36*$G$8*($B$22^3-$C$34^3) -> 0 | M36: =-1*H36*$H$8*(1/$B$22-1/$C$34) -> 7.6373566 | O36: =SUM(J36:M36) -> 3119.3988 | P36: =O36*B36*$K$6 -> 291.61508 | T36: H2O | V36: 3.47 | W36: 1.45 | X36: 0 | Y36: 0.121 | AA36: =V36*($V$27-$V$26) -> -2255.5 | AB36: =(W36*$W$8*($V$27^2-$V$26^2))*(1/2) -> -893.63138 | AC36: =(1/3)*X36*$X$8*($V$27^3-$V$26^3) -> 0 | AD36: =Y36*$Y$8*(1/$V$27-1/$V$26) -> 9.9134896 | AF36: =SUM(AA36:AD36) -> -3139.2179 | AG36: ='MATERIAL BALANCE'!U10/(60*60*24) -> 0.036945023 | AH36: =AF36*AG36*8.314 -> -964.24506
A37: H2 | B37: =('MATERIAL BALANCE'!M6)/(60*60*24) -> 0.033732639 | E37: 3.249 | F37: 0.422 | G37: 0 | H37: 0.083 | J37: =-E37*($B$22-$C34) -> 2680.425 | K37: =-1*(F37*$F$8*($B$22^2-$C34^2))*(1/2) -> 247.4128 | L37: =-1*(1/3)*G37*$G$8*($B$22^3-$C$34^3) -> 0 | M37: =-1*H37*$H$8*(1/$B$22-1/$C$34) -> -20.448406 | O37: =SUM(J37:M37) -> 2907.3894 | P37: =O37*B37*$K$6 -> 815.38654 | T37: INERT | V37: 20.786 | W37: 0.123 | X37: =-0.136 -> -0.136 | Y37: 0 | AA37: =V37*($V$27-$V$26) -> -13510.9 | AB37: =(W37*$W$8*($V$27^2-$V$26^2))*(1/2) -> -75.804593 | AC37: =(1/3)*X37*$X$8*($V$27^3-$V$26^3) -> 82.582993 | AD37: =Y37*$Y$8*(1/$V$27-1/$V$26) -> 0 | AF37: =SUM(AA37:AD37) -> -13504.122 | AG37: ='MATERIAL BALANCE'!U6/(60*60*24) -> 0.00022662037 | AH37: =AF37*AG37*8.314 -> -25.443409 | AI37: =SUM(AH31:AH37) -> -2643.5316 | AJ37: DH
A38: H2O | B38: =('MATERIAL BALANCE'!M7)/(60*60*24) -> 0.036945023 | E38: 3.47 | F38: 1.45 | G38: 0 | H38: 0.121 | J38: =-E38*($B$22-$C34) -> 2862.75 | K38: =-1*(F38*$F$8*($B$22^2-$C34^2))*(1/2) -> 850.11506 | L38: =-1*(1/3)*G38*$G$8*($B$22^3-$C$34^3) -> 0 | M38: =-1*H38*$H$8*(1/$B$22-1/$C$34) -> -29.810327 | O38: =SUM(J38:M38) -> 3683.0547 | P38: =O38*B38*$K$6 -> 1131.2905 | Q38: =SUM(P35:P38) -> 2467.6723
T39: COOLER | U39: (Before CO2 removal)
P40: DH | Q40: =(Q38+Q30)+('MATERIAL BALANCE'!L13*('HEAT TRANSFER'!E24)*1000/(60*60*24)) -> 3401.2893
F41: SECONDRYREFORMER | T41: Tin | U41: 350 | V41: =273.15+U41 -> 623.15
A42: INPUTS | T42: Tout | U42: 110 | V42: =273.15+U42 -> 383.15
D43: del Hr | E43: =-36 -> -36
B44: 900 | C44: =273.15+B44 -> 1173.15 | U44: Cp | V44: A | W44: B | X44: C | Y44: D
A45: CH4 | B45: =('MATERIAL BALANCE'!S7)/(24*60*60) -> 0.0048188657 | E45: 1.702 | F45: 9.081 | G45: -2.164 | H45: 0 | J45: =E45*($B$22-$C44) -> -1489.25 | K45: =(F45*$F$8*($B$22^2-$C$44^2))*(1/2) -> -5845.3829 | L45: =(1/3)*G45*$G$8*($B$22^3-$C$44^3) -> 1145.5353 | M45: =H45*$H$8*(1/$B$22-1/$C$44) -> 0 | O45: =SUM(J45:M45) -> -6189.0976 | P45: =O45*B45*$K$6 -> -247.96032 | V45: 1 | W45: =0.001 -> 0.001 | X45: =0.000001 -> 1e-06 | Y45: =100000 -> 100000
...

Sheet Sheet1
